Workbook

Sheet Dataset
A1: Student_ID | B1: Student_Name | C1: Department | D1: Gender | E1: Semester | F1: Attendance_% | G1: Study_Hours | H1: Assignment_Score | I1: Midterm_Score | J1: Final_Exam_Score | K1: Projects_Completed | L1: Certifications | M1: Backlogs | N1: Internship | O1: Monthly_Stipend | P1: Placement_Status | Q1: Overall_Score | R1: GRADE | S1: PLACED FLAG | T1: AVG EXAM SCORE | U1: RANK | V1: UPPER_CASE | W1: STUDENT NO
A2: STU1001 | B2: Student_001 | C2: IT | D2: Female | E2: 6 | F2: 76.4 | G2: 1.9 | H2: 100 | I2: 76.4 | J2: 74.9 | K2: 2 | L2: 1 | M2: 0 | N2: No | O2: 0 | P2: Placed | Q2: 80.37 | R2: =IF(Q2>=KPI!$E$4,"A",IF(Q2>=KPI!$E$5,"B",IF(Q2>=KPI!$E$6,"C",IF(Q2>=KPI!$E$7,"D","F")))) -> B | S2: =IF(P2="Placed",1,0) -> 1 | T2: =IFERROR(AVERAGE(I2:J2),0) -> 75.65 | U2: =RANK(Q2,$Q$2:$Q$251,0)+COUNTIF($Q$2:Q2,Q2)-1 -> 79 | V2: =UPPER(B2) -> STUDENT_001 | W2: =IFERROR(MID(B2,FIND("_",B2)+1,LEN(B2)),B2) -> 001
A3: STU1002 | B3: Student_002 | C3: Electronics | D3: Female | E3: 7 | F3: 62.3 | G3: 5.8 | H3: 69.6 | I3: 72 | J3: 66.1 | K3: 2 | L3: 0 | M3: 0 | N3: No | O3: 0 | P3: Not Placed | Q3: 68.57 | R3: =IF(Q3>=KPI!$E$4,"A",IF(Q3>=KPI!$E$5,"B",IF(Q3>=KPI!$E$6,"C",IF(Q3>=KPI!$E$7,"D","F")))) -> C | S3: =IF(P3="Placed",1,0) -> 0 | T3: =IFERROR(AVERAGE(I3:J3),0) -> 69.05 | U3: =RANK(Q3,$Q$2:$Q$251,0)+COUNTIF($Q$2:Q3,Q3)-1 -> 197 | V3: =UPPER(B3) -> STUDENT_002 | W3: =IFERROR(MID(B3,FIND("_",B3)+1,LEN(B3)),B3) -> 002
A4: STU1003 | B4: Student_003 | C4: Data Science | D4: Male | E4: 1 | F4: 89.7 | G4: 8.4 | H4: 89.3 | I4: 77.8 | J4: 94 | K4: 5 | L4: 0 | M4: 2 | N4: Yes | O4: 12345 | P4: Not Placed | Q4: 88.2 | R4: =IF(Q4>=KPI!$E$4,"A",IF(Q4>=KPI!$E$5,"B",IF(Q4>=KPI!$E$6,"C",IF(Q4>=KPI!$E$7,"D","F")))) -> A | S4: =IF(P4="Placed",1,0) -> 0 | T4: =IFERROR(AVERAGE(I4:J4),0) -> 85.9 | U4: =RANK(Q4,$Q$2:$Q$251,0)+COUNTIF($Q$2:Q4,Q4)-1 -> 14 | V4: =UPPER(B4) -> STUDENT_003 | W4: =IFERROR(MID(B4,FIND("_",B4)+1,LEN(B4)),B4) -> 003
A5: STU1004 | B5: Student_004 | C5: AI-ML | D5: Female | E5: 1 | F5: 73.1 | G5: 6.1 | H5: 61.8 | I5: 61.2 | J5: 80 | K5: 5 | L5: 3 | M5: 1 | N5: No | O5: 0 | P5: Placed | Q5: 70.72 | R5: =IF(Q5>=KPI!$E$4,"A",IF(Q5>=KPI!$E$5,"B",IF(Q5>=KPI!$E$6,"C",IF(Q5>=KPI!$E$7,"D","F")))) -> C | S5: =IF(P5="Placed",1,0) -> 1 | T5: =IFERROR(AVERAGE(I5:J5),0) -> 70.6 | U5: =RANK(Q5,$Q$2:$Q$251,0)+COUNTIF($Q$2:Q5,Q5)-1 -> 179 | V5: =UPPER(B5) -> STUDENT_004 | W5: =IFERROR(MID(B5,FIND("_",B5)+1,LEN(B5)),B5) -> 004
A6: STU1005 | B6: Student_005 | C6: Computer Engineering | D6: Female | E6: 1 | G6: 4 | H6: 80.8 | I6: 51.9 | J6: 57.9 | K6: 2 | L6: 2 | M6: 0 | N6: No | O6: 0 | P6: Placed | Q6: 60.68 | R6: =IF(Q6>=KPI!$E$4,"A",IF(Q6>=KPI!$E$5,"B",IF(Q6>=KPI!$E$6,"C",IF(Q6>=KPI!$E$7,"D","F")))) -> D | S6: =IF(P6="Placed",1,0) -> 1 | T6: =IFERROR(AVERAGE(I6:J6),0) -> 54.9 | U6: =RANK(Q6,$Q$2:$Q$251,0)+COUNTIF($Q$2:Q6,Q6)-1 -> 239 | V6: =UPPER(B6) -> STUDENT_005 | W6: =IFERROR(MID(B6,FIND("_",B6)+1,LEN(B6)),B6) -> 005
A7: STU1006 | B7: Student_006 | C7: Computer Engineering | D7: Male | E7: 5 | F7: 90.7 | G7: 5.7 | H7: 82.2 | I7: 45.2 | J7: 62.7 | K7: 3 | L7: 2 | M7: 2 | N7: Yes | O7: 15558 | P7: Not Placed | Q7: 61.35 | R7: =IF(Q7>=KPI!$E$4,"A",IF(Q7>=KPI!$E$5,"B",IF(Q7>=KPI!$E$6,"C",IF(Q7>=KPI!$E$7,"D","F")))) -> D | S7: =IF(P7="Placed",1,0) -> 0 | T7: =IFERROR(AVERAGE(I7:J7),0) -> 53.95 | U7: =RANK(Q7,$Q$2:$Q$251,0)+COUNTIF($Q$2:Q7,Q7)-1 -> 235 | V7: =UPPER(B7) -> STUDENT_006 | W7: =IFERROR(MID(B7,FIND("_",B7)+1,LEN(B7)),B7) -> 006
A8: STU1007 | B8: Student_007 | C8: Computer Engineering | D8: Male | E8: 4 | F8: 73.2 | G8: 7.7 | H8: 75.7 | I8: 85.7 | J8: 84.4 | K8: 0 | L8: 0 | M8: 0 | N8: Yes | O8: 16506 | P8: Not Placed | Q8: 83.05 | R8: =IF(Q8>=KPI!$E$4,"A",IF(Q8>=KPI!$E$5,"B",IF(Q8>=KPI!$E$6,"C",IF(Q8>=KPI!$E$7,"D","F")))) -> B | S8: =IF(P8="Placed",1,0) -> 0 | T8: =IFERROR(AVERAGE(I8:J8),0) -> 85.05 | U8: =RANK(Q8,$Q$2:$Q$251,0)+COUNTIF($Q$2:Q8,Q8)-1 -> 56 | V8: =UPPER(B8) -> STUDENT_007 | W8: =IFERROR(MID(B8,FIND("_",B8)+1,LEN(B8)),B8) -> 007
A9: STU1008 | B9: Student_008 | C9: Electronics | D9: Male | E9: 5 | F9: 82.7 | G9: 7.6 | H9: 68.6 | I9: 87.5 | J9: 82.5 | K9: 0 | L9: 4 | M9: 0 | N9: No | O9: 0 | P9: Not Placed | Q9: 81.22 | R9: =IF(Q9>=KPI!$E$4,"A",IF(Q9>=KPI!$E$5,"B",IF(Q9>=KPI!$E$6,"C",IF(Q9>=KPI!$E$7,"D","F")))) -> B | S9: =IF(P9="Placed",1,0) -> 0 | T9: =IFERROR(AVERAGE(I9:J9),0) -> 85 | U9: =RANK(Q9,$Q$2:$Q$251,0)+COUNTIF($Q$2:Q9,Q9)-1 -> 69 | V9: =UPPER(B9) -> STUDENT_008 | W9: =IFERROR(MID(B9,FIND("_",B9)+1,LEN(B9)),B9) -> 008
A10: STU1009 | B10: Student_009 | C10: AI-ML | D10: Male | E10: 4 | F10: 95.7 | G10: 3 | H10: 72.6 | I10: 76.2 | J10: 71.9 | K10: 5 | L10: 1 | M10: 0 | N10: No | O10: 0 | P10: Placed | Q10: 73.33 | R10: =IF(Q10>=KPI!$E$4,"A",IF(Q10>=KPI!$E$5,"B",IF(Q10>=KPI!$E$6,"C",IF(Q10>=KPI!$E$7,"D","F")))) -> C | S10: =IF(P10="Placed",1,0) -> 1 | T10: =IFERROR(AVERAGE(I10:J10),0) -> 74.05 | U10: =RANK(Q10,$Q$2:$Q$251,0)+COUNTIF($Q$2:Q10,Q10)-1 -> 148 | V10: =UPPER(B10) -> STUDENT_009 | W10: =IFERROR(MID(B10,FIND("_",B10)+1,LEN(B10)),B10) -> 009
A11: STU1010 | B11: Student_010 | C11: Data Science | D11: Female | E11: 8 | F11: 59.9 | G11: 5.7 | H11: 70.8 | I11: 64.5 | J11: 55.4 | K11: 1 | L11: 4 | M11: 1 | N11: No | O11: 0 | P11: Not Placed | Q11: 61.21 | R11: =IF(Q11>=KPI!$E$4,"A",IF(Q11>=KPI!$E$5,"B",IF(Q11>=KPI!$E$6,"C",IF(Q11>=KPI!$E$7,"D","F")))) -> D | S11: =IF(P11="Placed",1,0) -> 0 | T11: =IFERROR(AVERAGE(I11:J11),0) -> 59.95 | U11: =RANK(Q11,$Q$2:$Q$251,0)+COUNTIF($Q$2:Q11,Q11)-1 -> 237 | V11: =UPPER(B11) -> STUDENT_010 | W11: =IFERROR(MID(B11,FIND("_",B11)+1,LEN(B11)),B11) -> 010
A12: STU1011 | B12: Student_011 | C12: Computer Engineering | D12: Male | E12: 5 | F12: 74.7 | G12: 4.5 | H12: 100 | I12: 49.3 | J12: 75.2 | K12: 5 | L12: 4 | M12: 1 | N12: No | O12: 0 | P12: Not Placed | Q12: 72.39 | R12: =IF(Q12>=KPI!$E$4,"A",IF(Q12>=KPI!$E$5,"B",IF(Q12>=KPI!$E$6,"C",IF(Q12>=KPI!$E$7,"D","F")))) -> C | S12: =IF(P12="Placed",1,0) -> 0 | T12: =IFERROR(AVERAGE(I12:J12),0) -> 62.25 | U12: =RANK(Q12,$Q$2:$Q$251,0)+COUNTIF($Q$2:Q12,Q12)-1 -> 158 | V12: =UPPER(B12) -> STUDENT_011 | W12: =IFERROR(MID(B12,FIND("_",B12)+1,LEN(B12)),B12) -> 011
A13: STU1012 | B13: Student_012 | C13: Electronics | D13: Male | E13: 5 | F13: 73.9 | G13: 6.3 | H13: 75.7 | I13: 79.9 | J13: 84.6 | K13: 5 | L13: 0 | M13: 0 | N13: No | O13: 0 | P13: Placed | Q13: 81.41 | R13: =IF(Q13>=KPI!$E$4,"A",IF(Q13>=KPI!$E$5,"B",IF(Q13>=KPI!$E$6,"C",IF(Q13>=KPI!$E$7,"D","F")))) -> B | S13: =IF(P13="Placed",1,0) -> 1 | T13: =IFERROR(AVERAGE(I13:J13),0) -> 82.25 | U13: =RANK(Q13,$Q$2:$Q$251,0)+COUNTIF($Q$2:Q13,Q13)-1 -> 67 | V13: =UPPER(B13) -> STUDENT_012 | W13: =IFERROR(MID(B13,FIND("_",B13)+1,LEN(B13)),B13) -> 012
A14: STU1013 | B14: Student_013 | C14: Data Science | D14: Female | E14: 6 | F14: 80.3 | G14: 5.5 | H14: 82.8 | I14: 56.6 | J14: 61.3 | K14: 0 | L14: 0 | M14: 2 | N14: No | O14: 0 | P14: Not Placed | Q14: 64.19 | R14: =IF(Q14>=KPI!$E$4,"A",IF(Q14>=KPI!$E$5,"B",IF(Q14>=KPI!$E$6,"C",IF(Q14>=KPI!$E$7,"D","F")))) -> D | S14: =IF(P14="Placed",1,0) -> 0 | T14: =IFERROR(AVERAGE(I14:J14),0) -> 58.95 | U14: =RANK(Q14,$Q$2:$Q$251,0)+COUNTIF($Q$2:Q14,Q14)-1 -> 222 | V14: =UPPER(B14) -> STUDENT_013 | W14: =IFERROR(MID(B14,FIND("_",B14)+1,LEN(B14)),B14) -> 013
A15: STU1014 | B15: Student_014 | C15: Computer Engineering | D15: Male | E15: 3 | F15: 81.6 | G15: 1 | H15: 99.2 | I15: 62 | J15: 81.2 | K15: 2 | L15: 0 | M15: 0 | N15: No | O15: 0 | P15: Placed | Q15: 79.04 | R15: =IF(Q15>=KPI!$E$4,"A",IF(Q15>=KPI!$E$5,"B",IF(Q15>=KPI!$E$6,"C",IF(Q15>=KPI!$E$7,"D","F")))) -> B | S15: =IF(P15="Placed",1,0) -> 1 | T15: =IFERROR(AVERAGE(I15:J15),0) -> 71.6 | U15: =RANK(Q15,$Q$2:$Q$251,0)+COUNTIF($Q$2:Q15,Q15)-1 -> 92 | V15: =UPPER(B15) -> STUDENT_014 | W15: =IFERROR(MID(B15,FIND("_",B15)+1,LEN(B15)),B15) -> 014
A16: STU1015 | B16: Student_015 | C16: Computer Engineering | D16: Male | E16: 5 | F16: 72.4 | G16: 4.2 | H16: 64.6 | I16: 63.8 | J16: 79.5 | K16: 5 | L16: 3 | M16: 0 | N16: No | O16: 0 | P16: Not Placed | Q16: 71.81 | R16: =IF(Q16>=KPI!$E$4,"A",IF(Q16>=KPI!$E$5,"B",IF(Q16>=KPI!$E$6,"C",IF(Q16>=KPI!$E$7,"D","F")))) -> C | S16: =IF(P16="Placed",1,0) -> 0 | T16: =IFERROR(AVERAGE(I16:J16),0) -> 71.65 | U16: =RANK(Q16,$Q$2:$Q$251,0)+COUNTIF($Q$2:Q16,Q16)-1 -> 163 | V16: =UPPER(B16) -> STUDENT_015 | W16: =IFERROR(MID(B16,FIND("_",B16)+1,LEN(B16)),B16) -> 015
A17: STU1016 | B17: Student_016 | C17: Computer Engineering | D17: Male | E17: 6 | F17: 76.1 | G17: 5.2 | H17: 76.5 | I17: 69.2 | J17: 70.6 | K17: 2 | L17: 4 | M17: 0 | N17: Yes | O17: 16690 | P17: Not Placed | Q17: 71.36 | R17: =IF(Q17>=KPI!$E$4,"A",IF(Q17>=KPI!$E$5,"B",IF(Q17>=KPI!$E$6,"C",IF(Q17>=KPI!$E$7,"D","F")))) -> C | S17: =IF(P17="Placed",1,0) -> 0 | T17: =IFERROR(AVERAGE(I17:J17),0) -> 69.9 | U17: =RANK(Q17,$Q$2:$Q$251,0)+COUNTIF($Q$2:Q17,Q17)-1 -> 170 | V17: =UPPER(B17) -> STUDENT_016 | W17: =IFERROR(MID(B17,FIND("_",B17)+1,LEN(B17)),B17) -> 016
A18: STU1017 | B18: Student_017 | C18: IT | D18: Male | E18: 2 | F18: 75 | G18: 2.2 | H18: 72.5 | I18: 61.4 | J18: 73.3 | K18: 2 | L18: 2 | M18: 0 | N18: No | O18: 0 | P18: Placed | Q18: 69.57 | R18: =IF(Q18>=KPI!$E$4,"A",IF(Q18>=KPI!$E$5,"B",IF(Q18>=KPI!$E$6,"C",IF(Q18>=KPI!$E$7,"D","F")))) -> C | S18: =IF(P18="Placed",1,0) -> 1 | T18: =IFERROR(AVERAGE(I18:J18),0) -> 67.35 | U18: =RANK(Q18,$Q$2:$Q$251,0)+COUNTIF($Q$2:Q18,Q18)-1 -> 194 | V18: =UPPER(B18) -> STUDENT_017 | W18: =IFERROR(MID(B18,FIND("_",B18)+1,LEN(B18)),B18) -> 017
... A24: STU1023 | B24: Student_023 | C24: IT | D24: Male | E24: 2 | F24: 74.1 | G24: 5.8 | H24: 88.9 | I24: 78.5 | J24: 84.9 | K24: 4 | L24: 4 | M24: 0 | N24: No | O24: 0 | P24: Placed | Q24: 83.78 | R24: =IF(Q24>=KPI!$E$4,"A",IF(Q24>=KPI!$E$5,"B",IF(Q24>=KPI!$E$6,"C",IF(Q24>=KPI!$E$7,"D","F")))) -> B | S24: =IF(P24="Placed",1,0) -> 1 | T24: =IFERROR(AVERAGE(I24:J24),0) -> 81.7 | U24: =RANK(Q24,$Q$2:$Q$251,0)+COUNTIF($Q$2:Q24,Q24)-1 -> 45 | V24: =UPPER(B24) -> STUDENT_023 | W24: =IFERROR(MID(B24,FIND("_",B24)+1,LEN(B24)),B24) -> 023
A25: STU1024 | B25: Student_024 | C25: IT | D25: Male | E25: 2 | F25: 82 | G25: 1.6 | H25: 84.1 | J25: 80.8 | K25: 5 | L25: 1 | M25: 0 | N25: Yes | O25: 17445 | P25: Not Placed | Q25: 87.22 | R25: =IF(Q25>=KPI!$E$4,"A",IF(Q25>=KPI!$E$5,"B",IF(Q25>=KPI!$E$6,"C",IF(Q25>=KPI!$E$7,"D","F")))) -> A | S25: =IF(P25="Placed",1,0) -> 0 | T25: =IFERROR(AVERAGE(I25:J25),0) -> 80.8 | U25: =RANK(Q25,$Q$2:$Q$251,0)+COUNTIF($Q$2:Q25,Q25)-1 -> 20 | V25: =UPPER(B25) -> STUDENT_024 | W25: =IFERROR(MID(B25,FIND("_",B25)+1,LEN(B25)),B25) -> 024
A26: STU1025 | B26: Student_025 | C26: IT | D26: Male | E26: 8 | F26: 100 | G26: 8.5 | I26: 55.6 | J26: 92.4 | K26: 0 | L26: 3 | M26: 0 | N26: Yes | O26: 5742 | P26: Not Placed | Q26: 76.8 | R26: =IF(Q26>=KPI!$E$4,"A",IF(Q26>=KPI!$E$5,"B",IF(Q26>=KPI!$E$6,"C",IF(Q26>=KPI!$E$7,"D","F")))) -> B | S26: =IF(P26="Placed",1,0) -> 0 | T26: =IFERROR(AVERAGE(I26:J26),0) -> 74 | U26: =RANK(Q26,$Q$2:$Q$251,0)+COUNTIF($Q$2:Q26,Q26)-1 -> 111 | V26: =UPPER(B26) -> STUDENT_025 | W26: =IFERROR(MID(B26,FIND("_",B26)+1,LEN(B26)),B26) -> 025
A27: STU1026 | B27: Student_026 | C27: Data Science | D27: Male | E27: 6 | F27: 91.1 | G27: 4.3 | H27: 70.2 | I27: 54.7 | J27: 82.2 | K27: 2 | L27: 3 | M27: 1 | N27: Yes | O27: 5306 | P27: Placed | Q27: 71.55 | R27: =IF(Q27>=KPI!$E$4,"A",IF(Q27>=KPI!$E$5,"B",IF(Q27>=KPI!$E$6,"C",IF(Q27>=KPI!$E$7,"D","F")))) -> C | S27: =IF(P27="Placed",1,0) -> 1 | T27: =IFERROR(AVERAGE(I27:J27),0) -> 68.45 | U27: =RANK(Q27,$Q$2:$Q$251,0)+COUNTIF($Q$2:Q27,Q27)-1 -> 168 | V27: =UPPER(B27) -> STUDENT_026 | W27: =IFERROR(MID(B27,FIND("_",B27)+1,LEN(B27)),B27) -> 026
A28: STU1027 | B28: Student_027 | C28: Computer Engineering | D28: Male | E28: 2 | F28: 78 | G28: 5 | H28: 79.6 | I28: 81.7 | J28: 93.7 | K28: 3 | L28: 1 | M28: 0 | N28: No | O28: 0 | P28: Placed | Q28: 87.28 | R28: =IF(Q28>=KPI!$E$4,"A",IF(Q28>=KPI!$E$5,"B",IF(Q28>=KPI!$E$6,"C",IF(Q28>=KPI!$E$7,"D","F")))) -> A | S28: =IF(P28="Placed",1,0) -> 1 | T28: =IFERROR(AVERAGE(I28:J28),0) -> 87.7 | U28: =RANK(Q28,$Q$2:$Q$251,0)+COUNTIF($Q$2:Q28,Q28)-1 -> 19 | V28: =UPPER(B28) -> STUDENT_027 | W28: =IFERROR(MID(B28,FIND("_",B28)+1,LEN(B28)),B28) -> 027
A29: STU1028 | B29: Student_028 | C29: AI-ML | D29: Male | E29: 3 | F29: 96.2 | G29: 5.1 | H29: 65.6 | I29: 99.3 | J29: 97.2 | K29: 0 | L29: 2 | M29: 1 | N29: Yes | O29: 16360 | P29: Placed | Q29: 91.51 | R29: =IF(Q29>=KPI!$E$4,"A",IF(Q29>=KPI!$E$5,"B",IF(Q29>=KPI!$E$6,"C",IF(Q29>=KPI!$E$7,"D","F")))) -> A | S29: =IF(P29="Placed",1,0) -> 1 | T29: =IFERROR(AVERAGE(I29:J29),0) -> 98.25 | U29: =RANK(Q29,$Q$2:$Q$251,0)+COUNTIF($Q$2:Q29,Q29)-1 -> 3 | V29: =UPPER(B29) -> STUDENT_028 | W29: =IFERROR(MID(B29,FIND("_",B29)+1,LEN(B29)),B29) -> 028
A30: STU1029 | B30: Student_029 | C30: AI-ML | D30: Male | E30: 5 | F30: 78.5 | G30: 5.9 | H30: 99.6 | I30: 68.4 | J30: 78.8 | K30: 3 | L30: 2 | M30: 2 | N30: No | O30: 0 | P30: Placed | Q30: 79.84 | R30: =IF(Q30>=KPI!$E$4,"A",IF(Q30>=KPI!$E$5,"B",IF(Q30>=KPI!$E$6,"C",IF(Q30>=KPI!$E$7,"D","F")))) -> B | S30: =IF(P30="Placed",1,0) -> 1 | T30: =IFERROR(AVERAGE(I30:J30),0) -> 73.6 | U30: =RANK(Q30,$Q$2:$Q$251,0)+COUNTIF($Q$2:Q30,Q30)-1 -> 84 | V30: =UPPER(B30) -> STUDENT_029 | W30: =IFERROR(MID(B30,FIND("_",B30)+1,LEN(B30)),B30) -> 029
A31: STU1030 | B31: Student_030 | C31: Computer Engineering | D31: Male | E31: 5 | F31: 76 | G31: 2.1 | H31: 80.7 | I31: 96.2 | J31: 88.7 | K31: 2 | L31: 3 | M31: 0 | N31: Yes | O31: 11519 | P31: Placed | Q31: 89.35 | R31: =IF(Q31>=KPI!$E$4,"A",IF(Q31>=KPI!$E$5,"B",IF(Q31>=KPI!$E$6,"C",IF(Q31>=KPI!$E$7,"D","F")))) -> A | S31: =IF(P31="Placed",1,0) -> 1 | T31: =IFERROR(AVERAGE(I31:J31),0) -> 92.45 | U31: =RANK(Q31,$Q$2:$Q$251,0)+COUNTIF($Q$2:Q31,Q31)-1 -> 9 | V31: =UPPER(B31) -> STUDENT_030 | W31: =IFERROR(MID(B31,FIND("_",B31)+1,LEN(B31)),B31) -> 030
A32: STU1031 | B32: Student_031 | C32: AI-ML | D32: Male | E32: 7 | F32: 94.6 | G32: 4.8 | H32: 81.1 | I32: 73.4 | J32: 81.8 | K32: 3 | L32: 3 | M32: 1 | N32: No | O32: 0 | P32: Placed | Q32: 79.14 | R32: =IF(Q32>=KPI!$E$4,"A",IF(Q32>=KPI!$E$5,"B",IF(Q32>=KPI!$E$6,"C",IF(Q32>=KPI!$E$7,"D","F")))) -> B | S32: =IF(P32="Placed",1,0) -> 1 | T32: =IFERROR(AVERAGE(I32:J32),0) -> 77.6 | U32: =RANK(Q32,$Q$2:$Q$251,0)+COUNTIF($Q$2:Q32,Q32)-1 -> 91 | V32: =UPPER(B32) -> STUDENT_031 | W32: =IFERROR(MID(B32,FIND("_",B32)+1,LEN(B32)),B32) -> 031
A33: STU1032 | B33: Student_032 | C33: Computer Engineering | D33: Female | E33: 8 | F33: 70.2 | G33: 3.6 | H33: 84.9 | I33: 62.5 | J33: 79.8 | K33: 5 | L33: 0 | M33: 0 | N33: No | O33: 0 | P33: Placed | Q33: 75.63 | R33: =IF(Q33>=KPI!$E$4,"A",IF(Q33>=KPI!$E$5,"B",IF(Q33>=KPI!$E$6,"C",IF(Q33>=KPI!$E$7,"D","F")))) -> B | S33: =IF(P33="Placed",1,0) -> 1 | T33: =IFERROR(AVERAGE(I33:J33),0) -> 71.15 | U33: =RANK(Q33,$Q$2:$Q$251,0)+COUNTIF($Q$2:Q33,Q33)-1 -> 124 | V33: =UPPER(B33) -> STUDENT_032 | W33: =IFERROR(MID(B33,FIND("_",B33)+1,LEN(B33)),B33) -> 032
A34: STU1033 | B34: Student_033 | C34: Computer Engineering | D34: Female | E34: 1 | F34: 64.8 | G34: 1.8 | H34: 68.5 | I34: 58.1 | J34: 67.6 | K34: 5 | L34: 2 | M34: 1 | N34: No | O34: 0 | P34: Placed | Q34: 64.93 | R34: =IF(Q34>=KPI!$E$4,"A",IF(Q34>=KPI!$E$5,"B",IF(Q34>=KPI!$E$6,"C",IF(Q34>=KPI!$E$7,"D","F")))) -> D | S34: =IF(P34="Placed",1,0) -> 1 | T34: =IFERROR(AVERAGE(I34:J34),0) -> 62.85 | U34: =RANK(Q34,$Q$2:$Q$251,0)+COUNTIF($Q$2:Q34,Q34)-1 -> 212 | V34: =UPPER(B34) -> STUDENT_033 | W34: =IFERROR(MID(B34,FIND("_",B34)+1,LEN(B34)),B34) -> 033
A35: STU1034 | B35: Student_034 | C35: Electronics | D35: Female | E35: 6 | F35: 90.5 | G35: 6.6 | H35: 90.2 | I35: 80.8 | J35: 85.7 | K35: 4 | L35: 1 | M35: 0 | N35: No | O35: 0 | P35: Placed | Q35: 85.13 | R35: =IF(Q35>=KPI!$E$4,"A",IF(Q35>=KPI!$E$5,"B",IF(Q35>=KPI!$E$6,"C",IF(Q35>=KPI!$E$7,"D","F")))) -> A | S35: =IF(P35="Placed",1,0) -> 1 | T35: =IFERROR(AVERAGE(I35:J35),0) -> 83.25 | U35: =RANK(Q35,$Q$2:$Q$251,0)+COUNTIF($Q$2:Q35,Q35)-1 -> 34 | V35: =UPPER(B35) -> STUDENT_034 | W35: =IFERROR(MID(B35,FIND("_",B35)+1,LEN(B35)),B35) -> 034
A36: STU1035 | B36: Student_035 | C36: Electronics | D36: Male | E36: 1 | F36: 82.2 | G36: 4.2 | H36: 77.5 | I36: 59.2 | J36: 77.5 | K36: 4 | L36: 2 | M36: 0 | N36: No | O36: 0 | P36: Placed | Q36: 72.01 | R36: =IF(Q36>=KPI!$E$4,"A",IF(Q36>=KPI!$E$5,"B",IF(Q36>=KPI!$E$6,"C",IF(Q36>=KPI!$E$7,"D","F")))) -> C | S36: =IF(P36="Placed",1,0) -> 1 | T36: =IFERROR(AVERAGE(I36:J36),0) -> 68.35 | U36: =RANK(Q36,$Q$2:$Q$251,0)+COUNTIF($Q$2:Q36,Q36)-1 -> 162 | V36: =UPPER(B36) -> STUDENT_035 | W36: =IFERROR(MID(B36,FIND("_",B36)+1,LEN(B36)),B36) -> 035
A37: STU1036 | B37: Student_036 | C37: Data Science | D37: Female | E37: 2 | F37: 83.1 | G37: 5.2 | H37: 88.4 | I37: 73.1 | J37: 86.8 | K37: 3 | L37: 0 | M37: 0 | N37: No | O37: 0 | P37: Placed | Q37: 83.01 | R37: =IF(Q37>=KPI!$E$4,"A",IF(Q37>=KPI!$E$5,"B",IF(Q37>=KPI!$E$6,"C",IF(Q37>=KPI!$E$7,"D","F")))) -> B | S37: =IF(P37="Placed",1,0) -> 1 | T37: =IFERROR(AVERAGE(I37:J37),0) -> 79.95 | U37: =RANK(Q37,$Q$2:$Q$251,0)+COUNTIF($Q$2:Q37,Q37)-1 -> 57 | V37: =UPPER(B37) -> STUDENT_036 | W37: =IFERROR(MID(B37,FIND("_",B37)+1,LEN(B37)),B37) -> 036
A38: STU1037 | B38: Student_037 | C38: IT | D38: Female | E38: 8 | F38: 78.7 | G38: 5.1 | H38: 73.4 | I38: 94.2 | J38: 67.3 | K38: 0 | L38: 3 | M38: 0 | N38: Yes | O38: 6555 | P38: Not Placed | Q38: 76.59 | R38: =IF(Q38>=KPI!$E$4,"A",IF(Q38>=KPI!$E$5,"B",IF(Q38>=KPI!$E$6,"C",IF(Q38>=KPI!$E$7,"D","F")))) -> B | S38: =IF(P38="Placed",1,0) -> 0 | T38: =IFERROR(AVERAGE(I38:J38),0) -> 80.75 | U38: =RANK(Q38,$Q$2:$Q$251,0)+COUNTIF($Q$2:Q38,Q38)-1 -> 115 | V38: =UPPER(B38) -> STUDENT_037 | W38: =IFERROR(MID(B38,FIND("_",B38)+1,LEN(B38)),B38) -> 037
... A61: STU1060 | B61: Student_060 | C61: IT | D61: Female | E61: 4 | F61: 73 | G61: 4.7 | H61: 64.3 | I61: 49.6 | J61: 67.8 | K61: 5 | L61: 4 | M61: 0 | N61: No | O61: 0 | P61: Not Placed | Q61: 61.64 | R61: =IF(Q61>=KPI!$E$4,"A",IF(Q61>=KPI!$E$5,"B",IF(Q61>=KPI!$E$6,"C",IF(Q61>=KPI!$E$7,"D","F")))) -> D | S61: =IF(P61="Placed",1,0) -> 0 | T61: =IFERROR(AVERAGE(I61:J61),0) -> 58.7 | U61: =RANK(Q61,$Q$2:$Q$251,0)+COUNTIF($Q$2:Q61,Q61)-1 -> 234 | V61: =UPPER(B61) -> STUDENT_060 | W61: =IFERROR(MID(B61,FIND("_",B61)+1,LEN(B61)),B61) -> 060
A62: STU1061 | B62: Student_061 | C62: IT | D62: Female | E62: 1 | F62: 84.5 | G62: 6.3 | H62: 55.7 | J62: 75.2 | K62: 0 | L62: 1 | M62: 2 | N62: No | O62: 0 | P62: Not Placed | Q62: 78.74 | R62: =IF(Q62>=KPI!$E$4,"A",IF(Q62>=KPI!$E$5,"B",IF(Q62>=KPI!$E$6,"C",IF(Q62>=KPI!$E$7,"D","F")))) -> B | S62: =IF(P62="Placed",1,0) -> 0 | T62: =IFERROR(AVERAGE(I62:J62),0) -> 75.2 | U62: =RANK(Q62,$Q$2:$Q$251,0)+COUNTIF($Q$2:Q62,Q62)-1 -> 95 | V62: =UPPER(B62) -> STUDENT_061 | W62: =IFERROR(MID(B62,FIND("_",B62)+1,LEN(B62)),B62) -> 061
A63: STU1062 | B63: Student_062 | C63: Computer Engineering | D63: Female | E63: 5 | F63: 57.3 | G63: 5 | H63: 100 | I63: 56.2 | J63: 72.9 | K63: 4 | L63: 3 | M63: 1 | N63: No | O63: 0 | P63: Not Placed | Q63: 73.31 | R63: =IF(Q63>=KPI!$E$4,"A",IF(Q63>=KPI!$E$5,"B",IF(Q63>=KPI!$E$6,"C",IF(Q63>=KPI!$E$7,"D","F")))) -> C | S63: =IF(P63="Placed",1,0) -> 0 | T63: =IFERROR(AVERAGE(I63:J63),0) -> 64.55 | U63: =RANK(Q63,$Q$2:$Q$251,0)+COUNTIF($Q$2:Q63,Q63)-1 -> 149 | V63: =UPPER(B63) -> STUDENT_062 | W63: =IFERROR(MID(B63,FIND("_",B63)+1,LEN(B63)),B63) -> 062
A64: STU1063 | B64: Student_063 | C64: Data Science | D64: Female | E64: 7 | F64: 77.9 | G64: 5.6 | H64: 74.6 | I64: 83.7 | J64: 90.3 | K64: 5 | L64: 3 | M64: 0 | N64: Yes | O64: 15120 | P64: Placed | Q64: 85.18 | R64: =IF(Q64>=KPI!$E$4,"A",IF(Q64>=KPI!$E$5,"B",IF(Q64>=KPI!$E$6,"C",IF(Q64>=KPI!$E$7,"D","F")))) -> A | S64: =IF(P64="Placed",1,0) -> 1 | T64: =IFERROR(AVERAGE(I64:J64),0) -> 87 | U64: =RANK(Q64,$Q$2:$Q$251,0)+COUNTIF($Q$2:Q64,Q64)-1 -> 33 | V64: =UPPER(B64) -> STUDENT_063 | W64: =IFERROR(MID(B64,FIND("_",B64)+1,LEN(B64)),B64) -> 063
A65: STU1064 | B65: Student_064 | C65: IT | D65: Male | E65: 5 | F65: 79.2 | G65: 4.4 | H65: 99.2 | I65: 72.4 | J65: 80.7 | K65: 0 | L65: 0 | M65: 0 | N65: No | O65: 0 | P65: Placed | Q65: 81.91 | R65: =IF(Q65>=KPI!$E$4,"A",IF(Q65>=KPI!$E$5,"B",IF(Q65>=KPI!$E$6,"C",IF(Q65>=KPI!$E$7,"D","F")))) -> B | S65: =IF(P65="Placed",1,0) -> 1 | T65: =IFERROR(AVERAGE(I65:J65),0) -> 76.55 | U65: =RANK(Q65,$Q$2:$Q$251,0)+COUNTIF($Q$2:Q65,Q65)-1 -> 63 | V65: =UPPER(B65) -> STUDENT_064 | W65: =IFERROR(MID(B65,FIND("_",B65)+1,LEN(B65)),B65) -> 064
A66: STU1065 | B66: Student_065 | C66: IT | D66: Male | E66: 6 | F66: 68.3 | G66: 6.8 | H66: 54.8 | I66: 75.5 | J66: 72.4 | K66: 5 | L66: 3 | M66: 2 | N66: Yes | O66: 13283 | P66: Not Placed | Q66: 69.81 | R66: =IF(Q66>=KPI!$E$4,"A",IF(Q66>=KPI!$E$5,"B",IF(Q66>=KPI!$E$6,"C",IF(Q66>=KPI!$E$7,"D","F")))) -> C | S66: =IF(P66="Placed",1,0) -> 0 | T66: =IFERROR(AVERAGE(I66:J66),0) -> 73.95 | U66: =RANK(Q66,$Q$2:$Q$251,0)+COUNTIF($Q$2:Q66,Q66)-1 -> 189 | V66: =UPPER(B66) -> STUDENT_065 | W66: =IFERROR(MID(B66,FIND("_",B66)+1,LEN(B66)),B66) -> 065
A67: STU1066 | B67: Student_066 | C67: AI-ML | D67: Male | E67: 3 | F67: 89.2 | H67: 68.6 | I67: 72 | J67: 79.6 | K67: 3 | L67: 0 | M67: 0 | N67: No | O67: 0 | P67: Placed | Q67: 75.12 | R67: =IF(Q67>=KPI!$E$4,"A",IF(Q67>=KPI!$E$5,"B",IF(Q67>=KPI!$E$6,"C",IF(Q67>=KPI!$E$7,"D","F")))) -> B | S67: =IF(P67="Placed",1,0) -> 1 | T67: =IFERROR(AVERAGE(I67:J67),0) -> 75.8 | U67: =RANK(Q67,$Q$2:$Q$251,0)+COUNTIF($Q$2:Q67,Q67)-1 -> 129 | V67: =UPPER(B67) -> STUDENT_066 | W67: =IFERROR(MID(B67,FIND("_",B67)+1,LEN(B67)),B67) -> 066
...

Sheet KPI
A1: KPI Summary Metrics
A3: TOTAL STUDENTS | B3: =IFERROR(COUNTA(Dataset!A2:A251),0) -> 250 | D3: GRADE | E3: MIN OVERALL SCORE | F3: STUDENTS
A4: AVERAGE OVERALL SCORE | B4: =IFERROR(AVERAGE(Dataset!Q2:Q251),0) -> 75.23112 | D4: A | E4: 85 | F4: =COUNTIF(Dataset!R2:R251,D4) -> 37
A5: PLACEMENT RATE | B5: =IFERROR(SUM(Dataset!S2:S251)/COUNTA(Dataset!A2:A251),0) -> 0.56 | D5: B | E5: 75 | F5: =COUNTIF(Dataset!R2:R251,D5) -> 98
A6: TOTAL PLACED | B6: =IFERROR(COUNTIF(Dataset!P2:P251,"Placed"),0) -> 140 | D6: C | E6: 65 | F6: =COUNTIF(Dataset!R2:R251,D6) -> 76
A7: TOTAL NOT PLACED | B7: =IFERROR(COUNTIF(Dataset!P2:P251,"Not Placed"),0) -> 110 | D7: D | E7: 50 | F7: =COUNTIF(Dataset!R2:R251,D7) -> 37
A8: AVERAGE ATTENDANCE % | B8: =IFERROR(AVERAGE(Dataset!F2:F251),0) -> 81.258776 | D8: F | E8: 0 | F8: =COUNTIF(Dataset!R2:R251,D8) -> 2
A9: AVERAGE STUDY HOURS / DAY | B9: =IFERROR(AVERAGE(Dataset!G2:G251),0) -> 4.76
A10: TOTAL PROJECTS COMPLETED | B10: =IFERROR(SUM(Dataset!K2:K251),0) -> 635
A11: TOTAL CERTIFICATIONS | B11: =IFERROR(SUM(Dataset!L2:L251),0) -> 526
A12: STUDENTS WITH BACKLOGS | B12: =IFERROR(COUNTIF(Dataset!M2:M251,">0"),0) -> 107
A13: INTERNSHIP RATE | B13: =IFERROR(COUNTIF(Dataset!N2:N251,"Yes")/COUNTA(Dataset!A2:A251),0) -> 0.416
A14: AVERAGE STIPEND (INTERNS) | B14: =IFERROR(AVERAGEIF(Dataset!O2:O251,">0"),0) -> 12343.346
A15: MISSING VALUES (BLANK CELLS) | B15: =COUNTBLANK(Dataset!A2:Q251) -> 20

Sheet HIGH-PERFORMING STUDENTS
A1: HIGH-PERFORMING STUDENTS
A3: TOP 10 STUDENTS BY OVERALL SCORE | E3: TOP DEPARTMENT BY AVG OVERALL SCORE
A4: NAME | B4: OVERALL SCORE | C4: DEPARTMENT
A5: =IFERROR(INDEX(Dataset!$B$2:$B$251,MATCH(ROWS($A$5:A5),Dataset!$U$2:$U$251,0)),"") -> Student_046 | B5: =IFERROR(INDEX(Dataset!$Q$2:$Q$251,MATCH(ROWS($A$5:A5),Dataset!$U$2:$U$251,0)),"") -> 93.65 | C5: =IFERROR(INDEX(Dataset!$C$2:$C$251,MATCH(ROWS($A$5:A5),Dataset!$U$2:$U$251,0)),"") -> AI-ML | E5: =INDEX(ANALYSIS!$A$4:$A$8,MATCH(MAX(ANALYSIS!$C$4:$C$8),ANALYSIS!$C$4:$C$8,0)) -> AI-ML
A6: =IFERROR(INDEX(Dataset!$B$2:$B$251,MATCH(ROWS($A$5:A6),Dataset!$U$2:$U$251,0)),"") -> Student_021 | B6: =IFERROR(INDEX(Dataset!$Q$2:$Q$251,MATCH(ROWS($A$5:A6),Dataset!$U$2:$U$251,0)),"") -> 91.62 | C6: =IFERROR(INDEX(Dataset!$C$2:$C$251,MATCH(ROWS($A$5:A6),Dataset!$U$2:$U$251,0)),"") -> AI-ML
A7: =IFERROR(INDEX(Dataset!$B$2:$B$251,MATCH(ROWS($A$5:A7),Dataset!$U$2:$U$251,0)),"") -> Student_028 | B7: =IFERROR(INDEX(Dataset!$Q$2:$Q$251,MATCH(ROWS($A$5:A7),Dataset!$U$2:$U$251,0)),"") -> 91.51 | C7: =IFERROR(INDEX(Dataset!$C$2:$C$251,MATCH(ROWS($A$5:A7),Dataset!$U$2:$U$251,0)),"") -> AI-ML | E7: LARGEST DEPARTMENT (MOST STUDENTS)
A8: =IFERROR(INDEX(Dataset!$B$2:$B$251,MATCH(ROWS($A$5:A8),Dataset!$U$2:$U$251,0)),"") -> Student_138 | B8: =IFERROR(INDEX(Dataset!$Q$2:$Q$251,MATCH(ROWS($A$5:A8),Dataset!$U$2:$U$251,0)),"") -> 91.45 | C8: =IFERROR(INDEX(Dataset!$C$2:$C$251,MATCH(ROWS($A$5:A8),Dataset!$U$2:$U$251,0)),"") -> Data Science
A9: =IFERROR(INDEX(Dataset!$B$2:$B$251,MATCH(ROWS($A$5:A9),Dataset!$U$2:$U$251,0)),"") -> Student_192 | B9: =IFERROR(INDEX(Dataset!$Q$2:$Q$251,MATCH(ROWS($A$5:A9),Dataset!$U$2:$U$251,0)),"") -> 91.33 | C9: =IFERROR(INDEX(Dataset!$C$2:$C$251,MATCH(ROWS($A$5:A9),Dataset!$U$2:$U$251,0)),"") -> Electronics | E9: =INDEX(ANALYSIS!$A$4:$A$8,MATCH(MAX(ANALYSIS!$B$4:$B$8),ANALYSIS!$B$4:$B$8,0)) -> Computer Engineering
A10: =IFERROR(INDEX(Dataset!$B$2:$B$251,MATCH(ROWS($A$5:A10),Dataset!$U$2:$U$251,0)),"") -> Student_116 | B10: =IFERROR(INDEX(Dataset!$Q$2:$Q$251,MATCH(ROWS($A$5:A10),Dataset!$U$2:$U$251,0)),"") -> 91.31 | C10: =IFERROR(INDEX(Dataset!$C$2:$C$251,MATCH(ROWS($A$5:A10),Dataset!$U$2:$U$251,0)),"") -> Electronics
A11: =IFERROR(INDEX(Dataset!$B$2:$B$251,MATCH(ROWS($A$5:A11),Dataset!$U$2:$U$251,0)),"") -> Student_215 | B11: =IFERROR(INDEX(Dataset!$Q$2:$Q$251,MATCH(ROWS($A$5:A11),Dataset!$U$2:$U$251,0)),"") -> 89.69 | C11: =IFERROR(INDEX(Dataset!$C$2:$C$251,MATCH(ROWS($A$5:A11),Dataset!$U$2:$U$251,0)),"") -> Data Science | E11: BEST DEPARTMENT BY PLACEMENT RATE
A12: =IFERROR(INDEX(Dataset!$B$2:$B$251,MATCH(ROWS($A$5:A12),Dataset!$U$2:$U$251,0)),"") -> Student_141 | B12: =IFERROR(INDEX(Dataset!$Q$2:$Q$251,MATCH(ROWS($A$5:A12),Dataset!$U$2:$U$251,0)),"") -> 89.54 | C12: =IFERROR(INDEX(Dataset!$C$2:$C$251,MATCH(ROWS($A$5:A12),Dataset!$U$2:$U$251,0)),"") -> Electronics
A13: =IFERROR(INDEX(Dataset!$B$2:$B$251,MATCH(ROWS($A$5:A13),Dataset!$U$2:$U$251,0)),"") -> Student_030 | B13: =IFERROR(INDEX(Dataset!$Q$2:$Q$251,MATCH(ROWS($A$5:A13),Dataset!$U$2:$U$251,0)),"") -> 89.35 | C13: =IFERROR(INDEX(Dataset!$C$2:$C$251,MATCH(ROWS($A$5:A13),Dataset!$U$2:$U$251,0)),"") -> Computer Engineering | E13: =INDEX(ANALYSIS!$A$4:$A$8,MATCH(MAX(ANALYSIS!$F$4:$F$8),ANALYSIS!$F$4:$F$8,0)) -> AI-ML
A14: =IFERROR(INDEX(Dataset!$B$2:$B$251,MATCH(ROWS($A$5:A14),Dataset!$U$2:$U$251,0)),"") -> Student_231 | B14: =IFERROR(INDEX(Dataset!$Q$2:$Q$251,MATCH(ROWS($A$5:A14),Dataset!$U$2:$U$251,0)),"") -> 88.74 | C14: =IFERROR(INDEX(Dataset!$C$2:$C$251,MATCH(ROWS($A$5:A14),Dataset!$U$2:$U$251,0)),"") -> Data Science
A18: UNIQUE STUDENT LIST
A19: NAME | B19: OVERALL SCORE | C19: PROJECTS | D19: PLACEMENT STATUS
A20: Student_001 | B20: =IFERROR(SUMIF(Dataset!B:B,A20,Dataset!Q:Q),0) -> 80.37 | C20: =IFERROR(SUMIF(Dataset!B:B,A20,Dataset!K:K),0) -> 2 | D20: =IFERROR(INDEX(Dataset!P:P,MATCH(A20,Dataset!B:B,0)),"Not Found") -> Placed
A21: Student_002 | B21: =IFERROR(SUMIF(Dataset!B:B,A21,Dataset!Q:Q),0) -> 68.57 | C21: =IFERROR(SUMIF(Dataset!B:B,A21,Dataset!K:K),0) -> 2 | D21: =IFERROR(INDEX(Dataset!P:P,MATCH(A21,Dataset!B:B,0)),"Not Found") -> Not Placed
A22: Student_003 | B22: =IFERROR(SUMIF(Dataset!B:B,A22,Dataset!Q:Q),0) -> 88.2 | C22: =IFERROR(SUMIF(Dataset!B:B,A22,Dataset!K:K),0) -> 5 | D22: =IFERROR(INDEX(Dataset!P:P,MATCH(A22,Dataset!B:B,0)),"Not Found") -> Not Placed
A23: Student_004 | B23: =IFERROR(SUMIF(Dataset!B:B,A23,Dataset!Q:Q),0) -> 70.72 | C23: =IFERROR(SUMIF(Dataset!B:B,A23,Dataset!K:K),0) -> 5 | D23: =IFERROR(INDEX(Dataset!P:P,MATCH(A23,Dataset!B:B,0)),"Not Found") -> Placed
A24: Student_005 | B24: =IFERROR(SUMIF(Dataset!B:B,A24,Dataset!Q:Q),0) -> 60.68 | C24: =IFERROR(SUMIF(Dataset!B:B,A24,Dataset!K:K),0) -> 2 | D24: =IFERROR(INDEX(Dataset!P:P,MATCH(A24,Dataset!B:B,0)),"Not Found") -> Placed
A25: Student_006 | B25: =IFERROR(SUMIF(Dataset!B:B,A25,Dataset!Q:Q),0) -> 61.35 | C25: =IFERROR(SUMIF(Dataset!B:B,A25,Dataset!K:K),0) -> 3 | D25: =IFERROR(INDEX(Dataset!P:P,MATCH(A25,Dataset!B:B,0)),"Not Found") -> Not Placed
A26: Student_007 | B26: =IFERROR(SUMIF(Dataset!B:B,A26,Dataset!Q:Q),0) -> 83.05 | C26: =IFERROR(SUMIF(Dataset!B:B,A26,Dataset!K:K),0) -> 0 | D26: =IFERROR(INDEX(Dataset!P:P,MATCH(A26,Dataset!B:B,0)),"Not Found") -> Not Placed
A27: Student_008 | B27: =IFERROR(SUMIF(Dataset!B:B,A27,Dataset!Q:Q),0) -> 81.22 | C27: =IFERROR(SUMIF(Dataset!B:B,A27,Dataset!K:K),0) -> 0 | D27: =IFERROR(INDEX(Dataset!P:P,MATCH(A27,Dataset!B:B,0)),"Not Found") -> Not Placed
A28: Student_009 | B28: =IFERROR(SUMIF(Dataset!B:B,A28,Dataset!Q:Q),0) -> 73.33 | C28: =IFERROR(SUMIF(Dataset!B:B,A28,Dataset!K:K),0) -> 5 | D28: =IFERROR(INDEX(Dataset!P:P,MATCH(A28,Dataset!B:B,0)),"Not Found") -> Placed
A29: Student_010 | B29: =IFERROR(SUMIF(Dataset!B:B,A29,Dataset!Q:Q),0) -> 61.21 | C29: =IFERROR(SUMIF(Dataset!B:B,A29,Dataset!K:K),0) -> 1 | D29: =IFERROR(INDEX(Dataset!P:P,MATCH(A29,Dataset!B:B,0)),"Not Found") -> Not Placed
A30: Student_011 | B30: =IFERROR(SUMIF(Dataset!B:B,A30,Dataset!Q:Q),0) -> 72.39 | C30: =IFERROR(SUMIF(Dataset!B:B,A30,Dataset!K:K),0) -> 5 | D30: =IFERROR(INDEX(Dataset!P:P,MATCH(A30,Dataset!B:B,0)),"Not Found") -> Not Placed
A31: Student_012 | B31: =IFERROR(SUMIF(Dataset!B:B,A31,Dataset!Q:Q),0) -> 81.41 | C31: =IFERROR(SUMIF(Dataset!B:B,A31,Dataset!K:K),0) -> 5 | D31: =IFERROR(INDEX(Dataset!P:P,MATCH(A31,Dataset!B:B,0)),"Not Found") -> Placed
... A269: Student_250 | B269: =IFERROR(SUMIF(Dataset!B:B,A269,Dataset!Q:Q),0) -> 81.76 | C269: =IFERROR(SUMIF(Dataset!B:B,A269,Dataset!K:K),0) -> 5 | D269: =IFERROR(INDEX(Dataset!P:P,MATCH(A269,Dataset!B:B,0)),"Not Found") -> Not Placed

Sheet ANALYSIS
A1: DEPARTMENT ANALYSIS
A3: UNIQUE DEPARTMENT | B3: TOTAL STUDENTS | C3: AVG OVERALL SCORE | D3: AVG ATTENDANCE % | E3: TOTAL CERTIFICATIONS | F3: PLACEMENT RATE
A4: AI-ML | B4: =IFERROR(COUNTIF(Dataset!C:C,A4),0) -> 48 | C4: =IFERROR(AVERAGEIF(Dataset!C:C,A4,Dataset!Q:Q),0) -> 77.141042 | D4: =IFERROR(AVERAGEIF(Dataset!C:C,A4,Dataset!F:F),0) -> 83.057447 | E4: =IFERROR(SUMIF(Dataset!C:C,A4,Dataset!L:L),0) -> 110 | F4: =IFERROR(SUMIF(Dataset!C:C,A4,Dataset!S:S)/B4,0) -> 0.66666667
A5: Computer Engineering | B5: =IFERROR(COUNTIF(Dataset!C:C,A5),0) -> 76 | C5: =IFERROR(AVERAGEIF(Dataset!C:C,A5,Dataset!Q:Q),0) -> 74.696053 | D5: =IFERROR(AVERAGEIF(Dataset!C:C,A5,Dataset!F:F),0) -> 80.417333 | E5: =IFERROR(SUMIF(Dataset!C:C,A5,Dataset!L:L),0) -> 176 | F5: =IFERROR(SUMIF(Dataset!C:C,A5,Dataset!S:S)/B5,0) -> 0.59210526
A6: Data Science | B6: =IFERROR(COUNTIF(Dataset!C:C,A6),0) -> 37 | C6: =IFERROR(AVERAGEIF(Dataset!C:C,A6,Dataset!Q:Q),0) -> 75.266757 | D6: =IFERROR(AVERAGEIF(Dataset!C:C,A6,Dataset!F:F),0) -> 79.980556 | E6: =IFERROR(SUMIF(Dataset!C:C,A6,Dataset!L:L),0) -> 58 | F6: =IFERROR(SUMIF(Dataset!C:C,A6,Dataset!S:S)/B6,0) -> 0.59459459
A7: Electronics | B7: =IFERROR(COUNTIF(Dataset!C:C,A7),0) -> 41 | C7: =IFERROR(AVERAGEIF(Dataset!C:C,A7,Dataset!Q:Q),0) -> 75.439756 | D7: =IFERROR(AVERAGEIF(Dataset!C:C,A7,Dataset!F:F),0) -> 80.3275 | E7: =IFERROR(SUMIF(Dataset!C:C,A7,Dataset!L:L),0) -> 79 | F7: =IFERROR(SUMIF(Dataset!C:C,A7,Dataset!S:S)/B7,0) -> 0.46341463
A8: IT | B8: =IFERROR(COUNTIF(Dataset!C:C,A8),0) -> 48 | C8: =IFERROR(AVERAGEIF(Dataset!C:C,A8,Dataset!Q:Q),0) -> 73.962708 | D8: =IFERROR(AVERAGEIF(Dataset!C:C,A8,Dataset!F:F),0) -> 82.574468 | E8: =IFERROR(SUMIF(Dataset!C:C,A8,Dataset!L:L),0) -> 103 | F8: =IFERROR(SUMIF(Dataset!C:C,A8,Dataset!S:S)/B8,0) -> 0.45833333
A9: ALL DEPARTMENTS | B9: =SUM(B4:B8) -> 250 | C9: =AVERAGE(Dataset!Q2:Q251) -> 75.23112 | D9: =AVERAGE(Dataset!F2:F251) -> 81.258776 | E9: =SUM(E4:E8) -> 526 | F9: =IFERROR(SUM(Dataset!S2:S251)/B9,0) -> 0.56
A12: CORRELATION ANALYSIS (PEARSON)
A13: RELATIONSHIP | B13: CORRELATION (r) | C13: STRENGTH | E13: STRENGTH CUT-OFFS | F13: |r| >=
A14: Attendance % vs Final Exam Score | B14: =IFERROR(CORREL(Dataset!F2:F251,Dataset!J2:J251),0) -> 0.27170946 | C14: =IF(ABS(B14)<$F$17,"Negligible",IF(ABS(B14)>=$F$15,"Strong",IF(ABS(B14)>=$F$16,"Moderate","Weak"))&IF(B14<0," negative"," positive")) -> Weak positive
A15: Study Hours vs Overall Score | B15: =IFERROR(CORREL(Dataset!G2:G251,Dataset!Q2:Q251),0) -> 0.21336574 | C15: =IF(ABS(B15)<$F$17,"Negligible",IF(ABS(B15)>=$F$15,"Strong",IF(ABS(B15)>=$F$16,"Moderate","Weak"))&IF(B15<0," negative"," positive")) -> Weak positive | E15: Strong | F15: 0.7
A16: Attendance % vs Overall Score | B16: =IFERROR(CORREL(Dataset!F2:F251,Dataset!Q2:Q251),0) -> 0.19424851 | C16: =IF(ABS(B16)<$F$17,"Negligible",IF(ABS(B16)>=$F$15,"Strong",IF(ABS(B16)>=$F$16,"Moderate","Weak"))&IF(B16<0," negative"," positive")) -> Negligible | E16: Moderate | F16: 0.4
A17: Final Exam Score vs Overall Score | B17: =IFERROR(CORREL(Dataset!J2:J251,Dataset!Q2:Q251),0) -> 0.9137858 | C17: =IF(ABS(B17)<$F$17,"Negligible",IF(ABS(B17)>=$F$15,"Strong",IF(ABS(B17)>=$F$16,"Moderate","Weak"))&IF(B17<0," negative"," positive")) -> Strong positive | E17: Weak | F17: 0.2
A18: Overall Score vs Placed (1/0) | B18: =IFERROR(CORREL(Dataset!Q2:Q251,Dataset!S2:S251),0) -> 0.20880783 | C18: =IF(ABS(B18)<$F$17,"Negligible",IF(ABS(B18)>=$F$15,"Strong",IF(ABS(B18)>=$F$16,"Moderate","Weak"))&IF(B18<0," negative"," positive")) -> Weak positive
A19: Backlogs vs Placed (1/0) | B19: =IFERROR(CORREL(Dataset!M2:M251,Dataset!S2:S251),0) -> -0.2107664 | C19: =IF(ABS(B19)<$F$17,"Negligible",IF(ABS(B19)>=$F$15,"Strong",IF(ABS(B19)>=$F$16,"Moderate","Weak"))&IF(B19<0," negative"," positive")) -> Weak negative
A20: Projects Completed vs Placed (1/0) | B20: =IFERROR(CORREL(Dataset!K2:K251,Dataset!S2:S251),0) -> 0.12074099 | C20: =IF(ABS(B20)<$F$17,"Negligible",IF(ABS(B20)>=$F$15,"Strong",IF(ABS(B20)>=$F$16,"Moderate","Weak"))&IF(B20<0," negative"," positive")) -> Negligible
A21: Certifications vs Placed (1/0) | B21: =IFERROR(CORREL(Dataset!L2:L251,Dataset!S2:S251),0) -> -0.037785716 | C21: =IF(ABS(B21)<$F$17,"Negligible",IF(ABS(B21)>=$F$15,"Strong",IF(ABS(B21)>=$F$16,"Moderate","Weak"))&IF(B21<0," negative"," positive")) -> Negligible

Sheet PIVOT TABLE
A1: PIVOT TABLE
A3: 1. AVERAGE OVERALL SCORE BY DEPARTMENT | T3: SCATTER DATA: Attendance vs Final Exam | W3: SCATTER DATA: Study Hours vs Overall
A4: Row Labels | B4: Average of Overall_Score | C4: Count of Student_ID | T4: Attendance_% | U4: Final_Exam_Score | W4: Study_Hours | X4: Overall_Score
A5: AI-ML | B5: =IFERROR(AVERAGEIF(Dataset!$C:$C,$A5,Dataset!$Q:$Q),0) -> 77.141042 | C5: =COUNTIF(Dataset!$C:$C,$A5) -> 48 | T5: =Dataset!F2 -> 76.4 | U5: =Dataset!J2 -> 74.9 | W5: =Dataset!G2 -> 1.9 | X5: =Dataset!Q2 -> 80.37
A6: Computer Engineering | B6: =IFERROR(AVERAGEIF(Dataset!$C:$C,$A6,Dataset!$Q:$Q),0) -> 74.696053 | C6: =COUNTIF(Dataset!$C:$C,$A6) -> 76 | T6: =Dataset!F3 -> 62.3 | U6: =Dataset!J3 -> 66.1 | W6: =Dataset!G3 -> 5.8 | X6: =Dataset!Q3 -> 68.57
A7: Data Science | B7: =IFERROR(AVERAGEIF(Dataset!$C:$C,$A7,Dataset!$Q:$Q),0) -> 75.266757 | C7: =COUNTIF(Dataset!$C:$C,$A7) -> 37 | T7: =Dataset!F4 -> 89.7 | U7: =Dataset!J4 -> 94 | W7: =Dataset!G4 -> 8.4 | X7: =Dataset!Q4 -> 88.2
A8: Electronics | B8: =IFERROR(AVERAGEIF(Dataset!$C:$C,$A8,Dataset!$Q:$Q),0) -> 75.439756 | C8: =COUNTIF(Dataset!$C:$C,$A8) -> 41 | T8: =Dataset!F5 -> 73.1 | U8: =Dataset!J5 -> 80 | W8: =Dataset!G5 -> 6.1 | X8: =Dataset!Q5 -> 70.72
A9: IT | B9: =IFERROR(AVERAGEIF(Dataset!$C:$C,$A9,Dataset!$Q:$Q),0) -> 73.962708 | C9: =COUNTIF(Dataset!$C:$C,$A9) -> 48 | T9: =Dataset!F7 -> 90.7 | U9: =Dataset!J7 -> 62.7 | W9: =Dataset!G6 -> 4 | X9: =Dataset!Q6 -> 60.68
A10: Grand Total | B10: =AVERAGE(Dataset!$Q$2:$Q$251) -> 75.23112 | C10: =SUM(C5:C9) -> 250 | T10: =Dataset!F8 -> 73.2 | U10: =Dataset!J8 -> 84.4 | W10: =Dataset!G7 -> 5.7 | X10: =Dataset!Q7 -> 61.35
T11: =Dataset!F9 -> 82.7 | U11: =Dataset!J9 -> 82.5 | W11: =Dataset!G8 -> 7.7 | X11: =Dataset!Q8 -> 83.05
A12: 2. PLACEMENT RATE BY DEPARTMENT | T12: =Dataset!F10 -> 95.7 | U12: =Dataset!J10 -> 71.9 | W12: =Dataset!G9 -> 7.6 | X12: =Dataset!Q9 -> 81.22
A13: Row Labels | B13: Placed | C13: Not Placed | D13: Total | E13: Placement Rate | T13: =Dataset!F11 -> 59.9 | U13: =Dataset!J11 -> 55.4 | W13: =Dataset!G10 -> 3 | X13: =Dataset!Q10 -> 73.33
A14: AI-ML | B14: =COUNTIFS(Dataset!$C:$C,$A14,Dataset!$P:$P,"Placed") -> 32 | C14: =COUNTIFS(Dataset!$C:$C,$A14,Dataset!$P:$P,"Not Placed") -> 16 | D14: =B14+C14 -> 48 | E14: =IFERROR(B14/D14,0) -> 0.66666667 | T14: =Dataset!F12 -> 74.7 | U14: =Dataset!J12 -> 75.2 | W14: =Dataset!G11 -> 5.7 | X14: =Dataset!Q11 -> 61.21
A15: Computer Engineering | B15: =COUNTIFS(Dataset!$C:$C,$A15,Dataset!$P:$P,"Placed") -> 45 | C15: =COUNTIFS(Dataset!$C:$C,$A15,Dataset!$P:$P,"Not Placed") -> 31 | D15: =B15+C15 -> 76 | E15: =IFERROR(B15/D15,0) -> 0.59210526 | T15: =Dataset!F13 -> 73.9 | U15: =Dataset!J13 -> 84.6 | W15: =Dataset!G12 -> 4.5 | X15: =Dataset!Q12 -> 72.39
A16: Data Science | B16: =COUNTIFS(Dataset!$C:$C,$A16,Dataset!$P:$P,"Placed") -> 22 | C16: =COUNTIFS(Dataset!$C:$C,$A16,Dataset!$P:$P,"Not Placed") -> 15 | D16: =B16+C16 -> 37 | E16: =IFERROR(B16/D16,0) -> 0.59459459 | T16: =Dataset!F14 -> 80.3 | U16: =Dataset!J14 -> 61.3 | W16: =Dataset!G13 -> 6.3 | X16: =Dataset!Q13 -> 81.41
A17: Electronics | B17: =COUNTIFS(Dataset!$C:$C,$A17,Dataset!$P:$P,"Placed") -> 19 | C17: =COUNTIFS(Dataset!$C:$C,$A17,Dataset!$P:$P,"Not Placed") -> 22 | D17: =B17+C17 -> 41 | E17: =IFERROR(B17/D17,0) -> 0.46341463 | T17: =Dataset!F15 -> 81.6 | U17: =Dataset!J15 -> 81.2 | W17: =Dataset!G14 -> 5.5 | X17: =Dataset!Q14 -> 64.19
A18: IT | B18: =COUNTIFS(Dataset!$C:$C,$A18,Dataset!$P:$P,"Placed") -> 22 | C18: =COUNTIFS(Dataset!$C:$C,$A18,Dataset!$P:$P,"Not Placed") -> 26 | D18: =B18+C18 -> 48 | E18: =IFERROR(B18/D18,0) -> 0.45833333 | T18: =Dataset!F16 -> 72.4 | U18: =Dataset!J16 -> 79.5 | W18: =Dataset!G15 -> 1 | X18: =Dataset!Q15 -> 79.04
A19: Grand Total | B19: =SUM(B14:B18) -> 140 | C19: =SUM(C14:C18) -> 110 | D19: =SUM(D14:D18) -> 250 | E19: =IFERROR(B19/D19,0) -> 0.56 | T19: =Dataset!F17 -> 76.1 | U19: =Dataset!J17 -> 70.6 | W19: =Dataset!G16 -> 4.2 | X19: =Dataset!Q16 -> 71.81
T20: =Dataset!F18 -> 75 | U20: =Dataset!J18 -> 73.3 | W20: =Dataset!G17 -> 5.2 | X20: =Dataset!Q17 -> 71.36
A21: 3. INTERNSHIP vs PLACEMENT STATUS | T21: =Dataset!F19 -> 78.8 | U21: =Dataset!J19 -> 74.7 | W21: =Dataset!G18 -> 2.2 | X21: =Dataset!Q18 -> 69.57
A22: Internship | B22: Placed | C22: Not Placed | D22: Total | E22: Placement Rate | T22: =Dataset!F20 -> 84 | U22: =Dataset!J20 -> 69.2 | W22: =Dataset!G19 -> 5.8 | X22: =Dataset!Q19 -> 74.08
A23: No | B23: =COUNTIFS(Dataset!$N:$N,$A23,Dataset!$P:$P,"Placed") -> 76 | C23: =COUNTIFS(Dataset!$N:$N,$A23,Dataset!$P:$P,"Not Placed") -> 70 | D23: =B23+C23 -> 146 | E23: =IFERROR(B23/D23,0) -> 0.52054795 | T23: =Dataset!F21 -> 90.2 | U23: =Dataset!J21 -> 72.4 | W23: =Dataset!G20 -> 2.1 | X23: =Dataset!Q20 -> 68.33
A24: Yes | B24: =COUNTIFS(Dataset!$N:$N,$A24,Dataset!$P:$P,"Placed") -> 64 | C24: =COUNTIFS(Dataset!$N:$N,$A24,Dataset!$P:$P,"Not Placed") -> 40 | D24: =B24+C24 -> 104 | E24: =IFERROR(B24/D24,0) -> 0.61538462 | T24: =Dataset!F22 -> 91.5 | U24: =Dataset!J22 -> 100 | W24: =Dataset!G21 -> 3.4 | X24: =Dataset!Q21 -> 74.04
A25: Grand Total | B25: =SUM(B23:B24) -> 140 | C25: =SUM(C23:C24) -> 110 | D25: =SUM(D23:D24) -> 250 | E25: =IFERROR(B25/D25,0) -> 0.56 | T25: =Dataset!F23 -> 87.9 | U25: =Dataset!J23 -> 70.5 | W25: =Dataset!G22 -> 7.2 | X25: =Dataset!Q22 -> 91.62
T26: =Dataset!F24 -> 74.1 | U26: =Dataset!J24 -> 84.9 | W26: =Dataset!G23 -> 3.2 | X26: =Dataset!Q23 -> 69.74
A27: 4. BACKLOGS vs PLACEMENT STATUS | T27: =Dataset!F25 -> 82 | U27: =Dataset!J25 -> 80.8 | W27: =Dataset!G24 -> 5.8 | X27: =Dataset!Q24 -> 83.78
A28: Backlogs | B28: Placed | C28: Not Placed | D28: Total | E28: Placement Rate | T28: =Dataset!F26 -> 100 | U28: =Dataset!J26 -> 92.4 | W28: =Dataset!G25 -> 1.6 | X28: =Dataset!Q25 -> 87.22
A29: 0 | B29: =COUNTIFS(Dataset!$M:$M,$A29,Dataset!$P:$P,"Placed") -> 90 | C29: =COUNTIFS(Dataset!$M:$M,$A29,Dataset!$P:$P,"Not Placed") -> 53 | D29: =B29+C29 -> 143 | E29: =IFERROR(B29/D29,0) -> 0.62937063 | T29: =Dataset!F27 -> 91.1 | U29: =Dataset!J27 -> 82.2 | W29: =Dataset!G26 -> 8.5 | X29: =Dataset!Q26 -> 76.8
A30: 1 | B30: =COUNTIFS(Dataset!$M:$M,$A30,Dataset!$P:$P,"Placed") -> 36 | C30: =COUNTIFS(Dataset!$M:$M,$A30,Dataset!$P:$P,"Not Placed") -> 24 | D30: =B30+C30 -> 60 | E30: =IFERROR(B30/D30,0) -> 0.6 | T30: =Dataset!F28 -> 78 | U30: =Dataset!J28 -> 93.7 | W30: =Dataset!G27 -> 4.3 | X30: =Dataset!Q27 -> 71.55
A31: 2 | B31: =COUNTIFS(Dataset!$M:$M,$A31,Dataset!$P:$P,"Placed") -> 9 | C31: =COUNTIFS(Dataset!$M:$M,$A31,Dataset!$P:$P,"Not Placed") -> 25 | D31: =B31+C31 -> 34 | E31: =IFERROR(B31/D31,0) -> 0.26470588 | T31: =Dataset!F29 -> 96.2 | U31: =Dataset!J29 -> 97.2 | W31: =Dataset!G28 -> 5 | X31: =Dataset!Q28 -> 87.28
A32: 3 | B32: =COUNTIFS(Dataset!$M:$M,$A32,Dataset!$P:$P,"Placed") -> 3 | C32: =COUNTIFS(Dataset!$M:$M,$A32,Dataset!$P:$P,"Not Placed") -> 6 | D32: =B32+C32 -> 9 | E32: =IFERROR(B32/D32,0) -> 0.33333333 | T32: =Dataset!F30 -> 78.5 | U32: =Dataset!J30 -> 78.8 | W32: =Dataset!G29 -> 5.1 | X32: =Dataset!Q29 -> 91.51
A33: 4 | B33: =COUNTIFS(Dataset!$M:$M,$A33,Dataset!$P:$P,"Placed") -> 2 | C33: =COUNTIFS(Dataset!$M:$M,$A33,Dataset!$P:$P,"Not Placed") -> 2 | D33: =B33+C33 -> 4 | E33: =IFERROR(B33/D33,0) -> 0.5 | T33: =Dataset!F31 -> 76 | U33: =Dataset!J31 -> 88.7 | W33: =Dataset!G30 -> 5.9 | X33: =Dataset!Q30 -> 79.84
A34: Grand Total | B34: =SUM(B29:B33) -> 140 | C34: =SUM(C29:C33) -> 110 | D34: =SUM(D29:D33) -> 250 | E34: =IFERROR(B34/D34,0) -> 0.56 | T34: =Dataset!F32 -> 94.6 | U34: =Dataset!J32 -> 81.8 | W34: =Dataset!G31 -> 2.1 | X34: =Dataset!Q31 -> 89.35
T35: =Dataset!F33 -> 70.2 | U35: =Dataset!J33 -> 79.8 | W35: =Dataset!G32 -> 4.8 | X35: =Dataset!Q32 -> 79.14
A36: 5. GENDER-WISE AVERAGE SCORE | T36: =Dataset!F34 -> 64.8 | U36: =Dataset!J34 -> 67.6 | W36: =Dataset!G33 -> 3.6 | X36: =Dataset!Q33 -> 75.63
A37: Row Labels | B37: Average of Overall_Score | C37: Average of Final_Exam_Score | D37: Count of Student_ID | T37: =Dataset!F35 -> 90.5 | U37: =Dataset!J35 -> 85.7 | W37: =Dataset!G34 -> 1.8 | X37: =Dataset!Q34 -> 64.93
A38: Female | B38: =IFERROR(AVERAGEIF(Dataset!$D:$D,$A38,Dataset!$Q:$Q),0) -> 74.595175 | C38: =IFERROR(AVERAGEIF(Dataset!$D:$D,$A38,Dataset!$J:$J),0) -> 75.72193 | D38: =COUNTIF(Dataset!$D:$D,$A38) -> 114 | T38: =Dataset!F36 -> 82.2 | U38: =Dataset!J36 -> 77.5 | W38: =Dataset!G35 -> 6.6 | X38: =Dataset!Q35 -> 85.13
A39: Male | B39: =IFERROR(AVERAGEIF(Dataset!$D:$D,$A39,Dataset!$Q:$Q),0) -> 75.764191 | C39: =IFERROR(AVERAGEIF(Dataset!$D:$D,$A39,Dataset!$J:$J),0) -> 77.964706 | D39: =COUNTIF(Dataset!$D:$D,$A39) -> 136 | T39: =Dataset!F37 -> 83.1 | U39: =Dataset!J37 -> 86.8 | W39: =Dataset!G36 -> 4.2 | X39: =Dataset!Q36 -> 72.01
A40: Grand Total | B40: =AVERAGE(Dataset!$Q$2:$Q$251) -> 75.23112 | C40: =AVERAGE(Dataset!$J$2:$J$251) -> 76.942 | D40: =SUM(D38:D39) -> 250 | T40: =Dataset!F38 -> 78.7 | U40: =Dataset!J38 -> 67.3 | W40: =Dataset!G37 -> 5.2 | X40: =Dataset!Q37 -> 83.01
T41: =Dataset!F39 -> 79.9 | U41: =Dataset!J39 -> 83.7 | W41: =Dataset!G38 -> 5.1 | X41: =Dataset!Q38 -> 76.59
...

Sheet CHARTS
